mplus_output/uni-16-ELSA_W2.out
Mplus VERSION 8.1 (Mac)
MUTHEN & MUTHEN
04/23/2020  10:56 PM

INPUT INSTRUCTIONS

  DATA:
  FILE = "uni-16-ELSA_W2.dat";

  VARIABLE:
  NAMES = mplusid UDAT UDAY UMON UYER UIWR UDWR UANI ULET UHL1 UHL2 UHL3 UHL4 UPM3;
   MISSING=.;
   CATEGORICAL ARE all; idvariable = mplusid;
  ANALYSIS:
  estimator = wlsmv; coverage=0;
  MODEL:
  g by UDAT * ;
   g by UDAY * ;
   g by UMON * ;
   g by UYER * ;
   g by UIWR * ;
   g by UDWR * ;
   g by UANI * ;
   g by ULET * ;
   g by UPM3 * ;
   g by UHL1 * ;
   g by UHL2 * ;
   g by UHL3 * ;
   g by UHL4 * ;
   g @ 1;

  OUTPUT:
  standardized; svalues;



*** WARNING
  Data set contains cases with missing on all variables.
  These cases were not included in the analysis.
  Number of cases with missing on all variables:  153
   1 WARNING(S) FOUND IN THE INPUT INSTRUCTIONS




SUMMARY OF ANALYSIS

Number of groups                                                 1
Number of observations                                        9279

Number of dependent variables                                   13
Number of independent variables                                  0
Number of continuous latent variables                            1

Observed dependent variables

  Binary and ordered categorical (ordinal)
   UDAT        UDAY        UMON        UYER        UIWR        UDWR
   UANI        ULET        UHL1        UHL2        UHL3        UHL4
   UPM3

Continuous latent variables
   G

Variables with special functions

  ID variable           MPLUSID

Estimator                                                    WLSMV
Maximum number of iterations                                  1000
Convergence criterion                                    0.500D-04
Maximum number of steepest descent iterations                   20
Maximum number of iterations for H1                           2000
Convergence criterion for H1                             0.100D-03
Parameterization                                             DELTA
Link                                                        PROBIT

Input data file(s)
  uni-16-ELSA_W2.dat

Input data format  FREE


SUMMARY OF DATA

     Number of missing data patterns            32


COVARIANCE COVERAGE OF DATA

Minimum covariance coverage value   0.000


     PROPORTION OF DATA PRESENT


           Covariance Coverage
              UDAT          UDAY          UMON          UYER          UIWR
              ________      ________      ________      ________      ________
 UDAT           0.997
 UDAY           0.997         0.997
 UMON           0.997         0.997         0.997
 UYER           0.997         0.997         0.997         0.997
 UIWR           0.995         0.995         0.995         0.995         0.996
 UDWR           0.995         0.995         0.995         0.995         0.995
 UANI           0.995         0.995         0.995         0.995         0.995
 ULET           0.966         0.966         0.966         0.966         0.966
 UHL1           0.959         0.959         0.959         0.959         0.959
 UHL2           0.959         0.959         0.959         0.959         0.958
 UHL3           0.958         0.958         0.958         0.958         0.958
 UHL4           0.959         0.959         0.959         0.959         0.959
 UPM3           0.892         0.892         0.892         0.892         0.891


           Covariance Coverage
              UDWR          UANI          ULET          UHL1          UHL2
              ________      ________      ________      ________      ________
 UDWR           0.997
 UANI           0.997         0.997
 ULET           0.966         0.966         0.966
 UHL1           0.959         0.959         0.948         0.959
 UHL2           0.958         0.958         0.947         0.958         0.959
 UHL3           0.958         0.958         0.947         0.958         0.958
 UHL4           0.959         0.959         0.948         0.959         0.959
 UPM3           0.892         0.892         0.869         0.868         0.867


           Covariance Coverage
              UHL3          UHL4          UPM3
              ________      ________      ________
 UHL3           0.958
 UHL4           0.958         0.959
 UPM3           0.867         0.868         0.894


UNIVARIATE PROPORTIONS AND COUNTS FOR CATEGORICAL VARIABLES

    UDAT
      Category 1    0.185         1709.000
      Category 2    0.815         7544.000
    UDAY
      Category 1    0.022          200.000
      Category 2    0.978         9054.000
    UMON
      Category 1    0.024          221.000
      Category 2    0.976         9033.000
    UYER
      Category 1    0.021          194.000
      Category 2    0.979         9060.000
    UIWR
      Category 1    0.008           77.000
      Category 2    0.027          251.000
      Category 3    0.020          183.000
      Category 4    0.052          477.000
      Category 5    0.119         1095.000
      Category 6    0.440         4065.000
      Category 7    0.197         1824.000
      Category 8    0.101          936.000
      Category 9    0.031          287.000
      Category 10    0.005           44.000
    UDWR
      Category 1    0.076          707.000
      Category 2    0.041          383.000
      Category 3    0.067          620.000
      Category 4    0.133         1229.000
      Category 5    0.193         1783.000
      Category 6    0.352         3259.000
      Category 7    0.087          808.000
      Category 8    0.036          330.000
      Category 9    0.011          103.000
      Category 10    0.003           27.000
    UANI
      Category 1    0.011          102.000
      Category 2    0.006           59.000
      Category 3    0.029          272.000
      Category 4    0.107          987.000
      Category 5    0.212         1963.000
      Category 6    0.254         2350.000
      Category 7    0.202         1869.000
      Category 8    0.105          975.000
      Category 9    0.045          419.000
      Category 10    0.028          256.000
    ULET
      Category 1    0.015          130.000
      Category 2    0.048          430.000
      Category 3    0.113         1009.000
      Category 4    0.262         2352.000
      Category 5    0.235         2105.000
      Category 6    0.229         2053.000
      Category 7    0.045          401.000
      Category 8    0.028          251.000
      Category 9    0.012          106.000
      Category 10    0.014          125.000
    UHL1
      Category 1    0.029          260.000
      Category 2    0.971         8636.000
    UHL2
      Category 1    0.190         1690.000
      Category 2    0.810         7204.000
    UHL3
      Category 1    0.094          840.000
      Category 2    0.906         8053.000
    UHL4
      Category 1    0.179         1591.000
      Category 2    0.821         7306.000
    UPM3
      Category 1    0.033          277.000
      Category 2    0.252         2089.000
      Category 3    0.024          197.000
      Category 4    0.033          270.000
      Category 5    0.659         5464.000



THE MODEL ESTIMATION TERMINATED NORMALLY



MODEL FIT INFORMATION

Number of Free Parameters                       61

Chi-Square Test of Model Fit

          Value                           2492.149*
          Degrees of Freedom                    65
          P-Value                           0.0000

*   The chi-square value for MLM, MLMV, MLR, ULSMV, WLSM and WLSMV cannot be used
    for chi-square difference testing in the regular way.  MLM, MLR and WLSM
    chi-square difference testing is described on the Mplus website.  MLMV, WLSMV,
    and ULSMV difference testing is done using the DIFFTEST option.

RMSEA (Root Mean Square Error Of Approximation)

          Estimate                           0.063
          90 Percent C.I.                    0.061  0.066
          Probability RMSEA <= .05           0.000

CFI/TLI

          CFI                                0.948
          TLI                                0.937

Chi-Square Test of Model Fit for the Baseline Model
